<!--
  Robocept robot URDF with Ignition Gazebo (Fortress) simulation plugins.

  4-wheeled differential-drive robot with:
    - LiDAR (RPLIDAR A2 equivalent) on top
    - RGBD camera (RealSense D435i equivalent) at front
    - Diff-drive plugin for /cmd_vel and /odom
    - GPU lidar plugin for /robocept/lidar/scan
    - RGBD camera plugin for color + depth

  Ignition topics are bridged to ROS 2 via ros_gz_bridge in the launch file.
-->
<robot xmlns:xacro="http://www.ros.org/wiki/xacro" name="robocept">

  <!-- ============== Properties ============== -->
  <xacro:property name="chassis_length" value="0.30"/>
  <xacro:property name="chassis_width" value="0.25"/>
  <xacro:property name="chassis_height" value="0.08"/>
  <xacro:property name="chassis_mass" value="3.0"/>

  <xacro:property name="wheel_radius" value="0.04"/>
  <xacro:property name="wheel_width" value="0.03"/>
  <xacro:property name="wheel_mass" value="0.2"/>
  <xacro:property name="wheel_separation" value="0.28"/>

  <!-- ============== Macros ============== -->
  <xacro:macro name="inertial_box" params="mass x y z">
    <inertial>
      <mass value="${mass}"/>
      <inertia ixx="${mass*(y*y+z*z)/12}" ixy="0" ixz="0"
               iyy="${mass*(x*x+z*z)/12}" iyz="0"
               izz="${mass*(x*x+y*y)/12}"/>
    </inertial>
  </xacro:macro>

  <xacro:macro name="inertial_cylinder" params="mass r l">
    <inertial>
      <mass value="${mass}"/>
      <inertia ixx="${mass*(3*r*r+l*l)/12}" ixy="0" ixz="0"
               iyy="${mass*(3*r*r+l*l)/12}" iyz="0"
               izz="${mass*r*r/2}"/>
    </inertial>
  </xacro:macro>

  <xacro:macro name="wheel" params="name x_offset y_offset">
    <link name="${name}_wheel_link">
      <visual>
        <geometry>
          <cylinder radius="${wheel_radius}" length="${wheel_width}"/>
        </geometry>
        <material name="dark_grey">
          <color rgba="0.2 0.2 0.2 1"/>
        </material>
      </visual>
      <collision>
        <geometry>
          <cylinder radius="${wheel_radius}" length="${wheel_width}"/>
        </geometry>
      </collision>
      <xacro:inertial_cylinder mass="${wheel_mass}" r="${wheel_radius}" l="${wheel_width}"/>
    </link>
    <joint name="${name}_wheel_joint" type="continuous">
      <parent link="base_link"/>
      <child link="${name}_wheel_link"/>
      <origin xyz="${x_offset} ${y_offset} 0" rpy="${-pi/2} 0 0"/>
      <axis xyz="0 0 1"/>
    </joint>
  </xacro:macro>

  <!-- ============== Base ============== -->
  <link name="base_footprint"/>

  <link name="base_link">
    <visual>
      <geometry>
        <box size="${chassis_length} ${chassis_width} ${chassis_height}"/>
      </geometry>
      <origin xyz="0 0 ${chassis_height/2 + wheel_radius}"/>
      <material name="blue">
        <color rgba="0.1 0.3 0.8 1"/>
      </material>
    </visual>
    <collision>
      <geometry>
        <box size="${chassis_length} ${chassis_width} ${chassis_height}"/>
      </geometry>
      <origin xyz="0 0 ${chassis_height/2 + wheel_radius}"/>
    </collision>
    <xacro:inertial_box mass="${chassis_mass}"
                        x="${chassis_length}" y="${chassis_width}" z="${chassis_height}"/>
  </link>

  <joint name="base_footprint_joint" type="fixed">
    <parent link="base_footprint"/>
    <child link="base_link"/>
    <origin xyz="0 0 0" rpy="0 0 0"/>
  </joint>

  <!-- ============== Wheels ============== -->
  <xacro:wheel name="front_left"  x_offset="${chassis_length/4}"  y_offset="${wheel_separation/2}"/>
  <xacro:wheel name="front_right" x_offset="${chassis_length/4}"  y_offset="${-wheel_separation/2}"/>
  <xacro:wheel name="rear_left"   x_offset="${-chassis_length/4}" y_offset="${wheel_separation/2}"/>
  <xacro:wheel name="rear_right"  x_offset="${-chassis_length/4}" y_offset="${-wheel_separation/2}"/>

  <!-- ============== LiDAR ============== -->
  <link name="robocept_lidar_frame">
    <visual>
      <geometry>
        <cylinder radius="0.035" length="0.04"/>
      </geometry>
      <material name="black">
        <color rgba="0.1 0.1 0.1 1"/>
      </material>
    </visual>
    <collision>
      <geometry>
        <cylinder radius="0.035" length="0.04"/>
      </geometry>
    </collision>
    <xacro:inertial_cylinder mass="0.15" r="0.035" l="0.04"/>
  </link>

  <joint name="base_to_lidar" type="fixed">
    <parent link="base_link"/>
    <child link="robocept_lidar_frame"/>
    <origin xyz="0.0 0.0 ${chassis_height + wheel_radius + 0.02}" rpy="0 0 0"/>
  </joint>

  <!-- ============== Camera ============== -->
  <link name="camera_link">
    <visual>
      <geometry>
        <box size="0.025 0.09 0.025"/>
      </geometry>
      <material name="silver">
        <color rgba="0.7 0.7 0.7 1"/>
      </material>
    </visual>
    <collision>
      <geometry>
        <box size="0.025 0.09 0.025"/>
      </geometry>
    </collision>
    <xacro:inertial_box mass="0.072" x="0.025" y="0.09" z="0.025"/>
  </link>

  <joint name="base_to_camera" type="fixed">
    <parent link="base_link"/>
    <child link="camera_link"/>
    <origin xyz="${chassis_length/2} 0 ${chassis_height/2 + wheel_radius}" rpy="0 0 0"/>
  </joint>

  <link name="camera_color_optical_frame"/>
  <joint name="camera_optical_joint" type="fixed">
    <parent link="camera_link"/>
    <child link="camera_color_optical_frame"/>
    <origin xyz="0 0 0" rpy="${-pi/2} 0 ${-pi/2}"/>
  </joint>

  <!-- ============== Ignition Gazebo Plugins ============== -->

  <!-- Diff-drive controller (publishes on Ignition topics, bridged to ROS) -->
  <gazebo>
    <plugin filename="ignition-gazebo-diff-drive-system" name="ignition::gazebo::systems::DiffDrive">
      <left_joint>front_left_wheel_joint</left_joint>
      <left_joint>rear_left_wheel_joint</left_joint>
      <right_joint>front_right_wheel_joint</right_joint>
      <right_joint>rear_right_wheel_joint</right_joint>
      <wheel_separation>${wheel_separation}</wheel_separation>
      <wheel_radius>${wheel_radius}</wheel_radius>
      <max_linear_acceleration>2.0</max_linear_acceleration>
      <odom_publish_frequency>20</odom_publish_frequency>
      <topic>cmd_vel</topic>
      <odom_topic>odom</odom_topic>
      <tf_topic>tf</tf_topic>
      <frame_id>odom</frame_id>
      <child_frame_id>base_footprint</child_frame_id>
    </plugin>
  </gazebo>

  <!-- LiDAR sensor (GPU lidar in Ignition) -->
  <gazebo reference="robocept_lidar_frame">
    <sensor name="rplidar" type="gpu_lidar">
      <always_on>true</always_on>
      <update_rate>10</update_rate>
      <visualize>true</visualize>
      <topic>lidar/scan</topic>
      <lidar>
        <scan>
          <horizontal>
            <samples>360</samples>
            <resolution>1</resolution>
            <min_angle>-3.14159</min_angle>
            <max_angle>3.14159</max_angle>
          </horizontal>
          <vertical>
            <samples>1</samples>
            <resolution>1</resolution>
            <min_angle>0</min_angle>
            <max_angle>0</max_angle>
          </vertical>
        </scan>
        <range>
          <min>0.15</min>
          <max>12.0</max>
          <resolution>0.01</resolution>
        </range>
        <noise>
          <type>gaussian</type>
          <mean>0.0</mean>
          <stddev>0.01</stddev>
        </noise>
      </lidar>
    </sensor>
  </gazebo>

  <!-- RGBD Camera (color + depth) -->
  <gazebo reference="camera_link">
    <sensor name="realsense" type="rgbd_camera">
      <always_on>true</always_on>
      <update_rate>15</update_rate>
      <topic>camera</topic>
      <camera>
        <horizontal_fov>1.2112</horizontal_fov>
        <image>
          <width>640</width>
          <height>480</height>
          <format>R8G8B8</format>
        </image>
        <clip>
          <near>0.1</near>
          <far>10.0</far>
        </clip>
        <depth_camera>
          <clip>
            <near>0.1</near>
            <far>10.0</far>
          </clip>
        </depth_camera>
        <noise>
          <type>gaussian</type>
          <mean>0.0</mean>
          <stddev>0.007</stddev>
        </noise>
      </camera>
    </sensor>
  </gazebo>

  <!-- Wheel friction -->
  <gazebo reference="front_left_wheel_link">
    <mu1>1.0</mu1><mu2>1.0</mu2>
  </gazebo>
  <gazebo reference="front_right_wheel_link">
    <mu1>1.0</mu1><mu2>1.0</mu2>
  </gazebo>
  <gazebo reference="rear_left_wheel_link">
    <mu1>1.0</mu1><mu2>1.0</mu2>
  </gazebo>
  <gazebo reference="rear_right_wheel_link">
    <mu1>1.0</mu1><mu2>1.0</mu2>
  </gazebo>

</robot>
